Workbook
Name Slicer_Region: #N/A
Name Slicer_Years: #N/A

Sheet Sheet2
A1: Retailer | B1: Retailer ID | C1: Invoice Date | D1: Region | E1: State | F1: City | G1: Beverage Brand | H1: Price per Unit | I1: Units Sold | J1: Total Sales | K1: Operating Profit | L1: Operating Margin
A2: BevCo | B2: 1185732 | C2: 44950 | D2: Northeast | E2: New Hampshire | F2: Manchester | G2: Coca-Cola | H2: 0.36 | I2: 1650 | J2: 594 | K2: 219.78 | L2: 0.37
A3: Amazon | B3: 1185732 | C3: 44947 | D3: Northeast | E3: Vermont | F3: Burlington | G3: Coca-Cola | H3: 0.34 | I3: 1730 | J3: 588.2 | K3: 252.926 | L3: 0.43
A4: Amazon | B4: 1185732 | C4: 44940 | D4: Northeast | E4: Massachusetts | F4: Boston | G4: Coca-Cola | H4: 0.35 | I4: 1790 | J4: 626.5 | K4: 325.78 | L4: 0.52
A5: FizzyCo | B5: 1185732 | C5: 44943 | D5: Northeast | E5: Rhode Island | F5: Providence | G5: Coca-Cola | H5: 0.28 | I5: 1400 | J5: 392 | K5: 129.36 | L5: 0.33
A6: BevCo | B6: 1185732 | C6: 44936 | D6: Northeast | E6: Connecticut | F6: Hartford | G6: Coca-Cola | H6: 0.23 | I6: 1490 | J6: 342.7 | K6: 143.934 | L6: 0.42
A7: Target | B7: 1197831 | C7: 44942 | D7: South | E7: Oklahoma | F7: Oklahoma City | G7: Coca-Cola | H7: 0.17 | I7: 1760 | J7: 299.2 | K7: 113.696 | L7: 0.38
A8: West Soda | B8: 1197831 | C8: 44949 | D8: South | E8: Arkansas | F8: Little Rock | G8: Coca-Cola | H8: 0.17 | I8: 1780 | J8: 302.6 | K8: 142.222 | L8: 0.47
A9: FizzyCo | B9: 1197831 | C9: 44949 | D9: South | E9: Mississippi | F9: Jackson | G9: Coca-Cola | H9: 0.17 | I9: 2150 | J9: 365.5 | K9: 160.82 | L9: 0.44
A10: BevCo | B10: 1185732 | C10: 44935 | D10: Southeast | E10: Georgia | F10: Atlanta | G10: Coca-Cola | H10: 0.26 | I10: 3490 | J10: 907.4 | K10: 426.478 | L10: 0.47
A11: FizzyCo | B11: 1128299 | C11: 44939 | D11: West | E11: New Mexico | F11: Albuquerque | G11: Coca-Cola | H11: 0.24 | I11: 1490 | J11: 357.6 | K11: 164.496 | L11: 0.46
A12: Target | B12: 1128299 | C12: 44952 | D12: West | E12: Arizona | F12: Phoenix | G12: Coca-Cola | H12: 0.27 | I12: 1520 | J12: 410.4 | K12: 168.264 | L12: 0.41
A13: BevCo | B13: 1128299 | C13: 44949 | D13: West | E13: Idaho | F13: Boise | G13: Coca-Cola | H13: 0.23 | I13: 1360 | J13: 312.8 | K13: 125.12 | L13: 0.4
... A1392: Walmart | B1392: 1128299 | C1392: 45276 | D1392: Southeast | E1392: Florida | F1392: Orlando | G1392: Coca-Cola | H1392: 0.75 | I1392: 8000 | J1392: 6000 | K1392: 1800 | L1392: 0.3

Sheet Data
B2: Retailer Dataset
B4: Retailer | C4: Retailer ID | D4: Invoice Date | E4: Region | F4: State | G4: City | H4: Beverage Brand | I4: Price per Unit | J4: Units Sold | K4: Total Sales | L4: Operating Profit | M4: Operating Margin
B5: BevCo | C5: 1185732 | D5: 44562 | E5: Northeast | F5: New York | G5: New York | H5: Coca-Cola | I5: 0.5 | J5: 12000 | K5: 6000 | L5: 3000 | M5: 0.5
B6: BevCo | C6: 1185732 | D6: 44563 | E6: Northeast | F6: New York | G6: New York | H6: Diet Coke | I6: 0.5 | J6: 10000 | K6: 5000 | L6: 1500 | M6: 0.3
B7: BevCo | C7: 1185732 | D7: 44564 | E7: Northeast | F7: New York | G7: New York | H7: Sprite | I7: 0.4 | J7: 10000 | K7: 4000 | L7: 1400 | M7: 0.35
B8: BevCo | C8: 1185732 | D8: 44565 | E8: Northeast | F8: New York | G8: New York | H8: Fanta | I8: 0.45 | J8: 8500 | K8: 3825 | L8: 1338.75 | M8: 0.35
B9: BevCo | C9: 1185732 | D9: 44566 | E9: Northeast | F9: New York | G9: New York | H9: Powerade | I9: 0.6 | J9: 9000 | K9: 5400 | L9: 1620 | M9: 0.3
B10: BevCo | C10: 1185732 | D10: 44567 | E10: Northeast | F10: New York | G10: New York | H10: Dasani Water | I10: 0.5 | J10: 10000 | K10: 5000 | L10: 1250 | M10: 0.25
B11: BevCo | C11: 1185732 | D11: 44568 | E11: Northeast | F11: New York | G11: New York | H11: Coca-Cola | I11: 0.5 | J11: 12500 | K11: 6250 | L11: 3125 | M11: 0.5
B12: BevCo | C12: 1185732 | D12: 44569 | E12: Northeast | F12: New York | G12: New York | H12: Diet Coke | I12: 0.5 | J12: 9000 | K12: 4500 | L12: 1350 | M12: 0.3
B13: BevCo | C13: 1185732 | D13: 44582 | E13: Northeast | F13: New York | G13: New York | H13: Sprite | I13: 0.4 | J13: 9500 | K13: 3800 | L13: 1330 | M13: 0.35
B14: BevCo | C14: 1185732 | D14: 44583 | E14: Northeast | F14: New York | G14: New York | H14: Fanta | I14: 0.45 | J14: 8250 | K14: 3712.5 | L14: 1299.375 | M14: 0.35
B15: BevCo | C15: 1185732 | D15: 44584 | E15: Northeast | F15: New York | G15: New York | H15: Powerade | I15: 0.6 | J15: 9000 | K15: 5400 | L15: 1620 | M15: 0.3
B16: BevCo | C16: 1185732 | D16: 44585 | E16: Northeast | F16: New York | G16: New York | H16: Dasani Water | I16: 0.5 | J16: 10000 | K16: 5000 | L16: 1250 | M16: 0.25
... B9652: BevCo | C9652: 1185732 | D9652: 44979 | E9652: Northeast | F9652: New Hampshire | G9652: Manchester | H9652: Sprite | I9652: 0.29 | J9652: 830 | K9652: 240.7 | L9652: 64.989 | M9652: 0.27

Sheet Sheet1
A1: Retailer | B1: Retailer ID | C1: Invoice Date | D1: Region | E1: State | F1: City | G1: Beverage Brand | H1: Price per Unit | I1: Units Sold | J1: Total Sales | K1: Operating Profit | L1: Operating Margin
A2: BevCo | B2: 1185732 | C2: 44562 | D2: Northeast | E2: New York | F2: New York | G2: Coca-Cola | H2: 0.5 | I2: 12000 | J2: 6000 | K2: 3000 | L2: 0.5
A3: West Soda | B3: 1128299 | C3: 44635 | D3: West | E3: Nevada | F3: Las Vegas | G3: Coca-Cola | H3: 0.2 | I3: 1490 | J3: 298 | K3: 119.2 | L3: 0.4
A4: West Soda | B4: 1128299 | C4: 44629 | D4: West | E4: Nevada | F4: Las Vegas | G4: Coca-Cola | H4: 0.47 | I4: 2160 | J4: 1015.2 | K4: 375.624 | L4: 0.37
A5: West Soda | B5: 1128299 | C5: 44623 | D5: West | E5: Nevada | F5: Las Vegas | G5: Coca-Cola | H5: 0.47 | I5: 1960 | J5: 921.2 | K5: 386.904 | L5: 0.42
A6: West Soda | B6: 1128299 | C6: 44617 | D6: West | E6: Nevada | F6: Las Vegas | G6: Coca-Cola | H6: 0.47 | I6: 1710 | J6: 803.7 | K6: 321.48 | L6: 0.4
A7: West Soda | B7: 1128299 | C7: 44611 | D7: West | E7: Nevada | F7: Las Vegas | G7: Coca-Cola | H7: 0.41 | I7: 1860 | J7: 762.6 | K7: 289.788 | L7: 0.38
A8: BevCo | B8: 1185732 | C8: 44568 | D8: Northeast | E8: New York | F8: New York | G8: Coca-Cola | H8: 0.5 | I8: 12500 | J8: 6250 | K8: 3125 | L8: 0.5
A9: West Soda | B9: 1128299 | C9: 44605 | D9: West | E9: Nevada | F9: Las Vegas | G9: Coca-Cola | H9: 0.44 | I9: 2380 | J9: 1047.2 | K9: 481.712 | L9: 0.46
A10: West Soda | B10: 1128299 | C10: 44599 | D10: West | E10: Nevada | F10: Las Vegas | G10: Coca-Cola | H10: 0.48 | I10: 2330 | J10: 1118.4 | K10: 492.096 | L10: 0.44
A11: West Soda | B11: 1128299 | C11: 44593 | D11: West | E11: Nevada | F11: Las Vegas | G11: Coca-Cola | H11: 0.47 | I11: 2450 | J11: 1151.5 | K11: 575.75 | L11: 0.5
A12: West Soda | B12: 1128299 | C12: 44587 | D12: West | E12: Nevada | F12: Las Vegas | G12: Coca-Cola | H12: 0.43 | I12: 1710 | J12: 735.3 | K12: 352.944 | L12: 0.48
A13: West Soda | B13: 1128299 | C13: 44581 | D13: West | E13: Nevada | F13: Las Vegas | G13: Coca-Cola | H13: 0.41 | I13: 1710 | J13: 701.1 | K13: 294.462 | L13: 0.42
... A220: West Soda | B220: 1128299 | C220: 44563 | D220: Northeast | E220: Pennsylvania | F220: Philadelphia | G220: Coca-Cola | H220: 0.35 | I220: 4500 | J220: 1575 | K220: 630 | L220: 0.4

Sheet Sheet3
A1: Retailer | B1: Retailer ID | C1: Invoice Date | D1: Region | E1: State | F1: City | G1: Beverage Brand | H1: Price per Unit | I1: Units Sold | J1: Total Sales | K1: Operating Profit | L1: Operating Margin
A2: BevCo | B2: 1185732 | C2: 44562 | D2: Northeast | E2: New York | F2: New York | G2: Coca-Cola | H2: 0.5 | I2: 12000 | J2: 6000 | K2: 3000 | L2: 0.5
A3: BevCo | B3: 1185732 | C3: 44563 | D3: Northeast | E3: New York | F3: New York | G3: Diet Coke | H3: 0.5 | I3: 10000 | J3: 5000 | K3: 1500 | L3: 0.3
A4: BevCo | B4: 1185732 | C4: 44564 | D4: Northeast | E4: New York | F4: New York | G4: Sprite | H4: 0.4 | I4: 10000 | J4: 4000 | K4: 1400 | L4: 0.35
A5: BevCo | B5: 1185732 | C5: 44565 | D5: Northeast | E5: New York | F5: New York | G5: Fanta | H5: 0.45 | I5: 8500 | J5: 3825 | K5: 1338.75 | L5: 0.35
A6: BevCo | B6: 1185732 | C6: 44566 | D6: Northeast | E6: New York | F6: New York | G6: Powerade | H6: 0.6 | I6: 9000 | J6: 5400 | K6: 1620 | L6: 0.3
A7: BevCo | B7: 1185732 | C7: 44567 | D7: Northeast | E7: New York | F7: New York | G7: Dasani Water | H7: 0.5 | I7: 10000 | J7: 5000 | K7: 1250 | L7: 0.25
A8: BevCo | B8: 1185732 | C8: 44568 | D8: Northeast | E8: New York | F8: New York | G8: Coca-Cola | H8: 0.5 | I8: 12500 | J8: 6250 | K8: 3125 | L8: 0.5
A9: BevCo | B9: 1185732 | C9: 44569 | D9: Northeast | E9: New York | F9: New York | G9: Diet Coke | H9: 0.5 | I9: 9000 | J9: 4500 | K9: 1350 | L9: 0.3
A10: BevCo | B10: 1185732 | C10: 44582 | D10: Northeast | E10: New York | F10: New York | G10: Sprite | H10: 0.4 | I10: 9500 | J10: 3800 | K10: 1330 | L10: 0.35
A11: BevCo | B11: 1185732 | C11: 44583 | D11: Northeast | E11: New York | F11: New York | G11: Fanta | H11: 0.45 | I11: 8250 | J11: 3712.5 | K11: 1299.375 | L11: 0.35
A12: BevCo | B12: 1185732 | C12: 44584 | D12: Northeast | E12: New York | F12: New York | G12: Powerade | H12: 0.6 | I12: 9000 | J12: 5400 | K12: 1620 | L12: 0.3
A13: BevCo | B13: 1185732 | C13: 44585 | D13: Northeast | E13: New York | F13: New York | G13: Dasani Water | H13: 0.5 | I13: 10000 | J13: 5000 | K13: 1250 | L13: 0.25
... A1303: Walmart | B1303: 1197831 | C1303: 44854 | D1303: South | E1303: Texas | F1303: Houston | G1303: Coca-Cola | H1303: 0.43 | I1303: 2340 | J1303: 1006.2 | K1303: 493.038 | L1303: 0.49

Sheet Analyze
A2: KPI
A3: 1.Total Sales
A4: 2. Display Average Operation Profit
A5: 3. Average Operating Profit
A7: Other information
A8: 1. Sales per Retailer
A9: 2.Sales per Beverages
A10: 3. Create Chart Visuals for the Sales(retailer and beverages)
D13: Sum of Total Sales
D14: 12016665
D16: Average of Operating Profit
D17: 489.47935
D19: Average of Operating Margin
D20: 0.42299129
D22: Count of Total Sales
D23: 9648
C25: Row Labels | D25: Count of Total Sales | E25: Sum of Units Sold
C26: Amazon | D26: 1005 | E26: 2496850
C27: BevCo | D27: 2618 | E27: 5852940
C28: FizzyCo | D28: 2017 | E28: 5465400
C29: Target | D29: 1030 | E29: 2873750
C30: Walmart | D30: 604 | E30: 1847050
C31: West Soda | D31: 2374 | E31: 6252620
C32: Grand Total | D32: 9648 | E32: 24788610
C34: Sum of Total Sales | D34: Column Labels
D35: 2022 | E35: 2023 | F35: Grand Total
C36: Row Labels
C37: Coca-Cola | D37: 499102 | E37: 2268974.9 | F37: 2768076.9
C38: Dasani Water | D38: 469270.7 | E38: 1917827.8 | F38: 2387098.5
C39: Diet Coke | D39: 423758.7 | E39: 1633959.3 | F39: 2057718
C40: Fanta | D40: 315489.2 | E40: 1116062.9 | F40: 1431552.1
C41: Powerade | D41: 349533.9 | E41: 1302529.3 | F41: 1652063.2
C42: Sprite | D42: 366578 | E42: 1353578.3 | F42: 1720156.3
C43: Grand Total | D43: 2423732.5 | E43: 9592932.5 | F43: 12016665
C45: Sum of Total Sales | D45: Column Labels
C46: Row Labels | D46: 2022 | E46: 2023
C47: Coca-Cola | D47: 499102 | E47: 2268974.9
C48: Dasani Water | D48: 469270.7 | E48: 1917827.8
C49: Diet Coke | D49: 423758.7 | E49: 1633959.3
C50: Fanta | D50: 315489.2 | E50: 1116062.9
...

Sheet Dashboard
C19: =Analyze!C34 -> Sum of Total Sales | D19: =Analyze!D34 -> Column Labels | J19: =Analyze!C54 -> Sum of Total Sales | K19: =Analyze!D54 -> Column Labels | L19: =Analyze!E54 -> 0
D20: =Analyze!D35 -> 2022 | E20: =Analyze!E35 -> 2023 | F20: =Analyze!F35 -> Grand Total | J20: =Analyze!C55 -> Row Labels | K20: =Analyze!D55 -> 2022 | L20: =Analyze!E55 -> 2023
C21: =Analyze!C36 -> Row Labels | F21: =Analyze!F3 -> 0 | J21: =Analyze!C56 -> Amazon | K21: =Analyze!D56 -> 276210 | L21: =Analyze!E56 -> 1009698.7
C22: =Analyze!C37 -> Coca-Cola | D22: =Analyze!D37 -> 499102 | E22: =Analyze!E37 -> 2268974.9 | F22: =Analyze!F37 -> 2768076.9 | J22: =Analyze!C57 -> BevCo | K22: =Analyze!D57 -> 466788 | L22: =Analyze!E57 -> 2327606.5
C23: =Analyze!C38 -> Dasani Water | D23: =Analyze!D38 -> 469270.7 | E23: =Analyze!E38 -> 1917827.8 | F23: =Analyze!F38 -> 2387098.5 | J23: =Analyze!C58 -> FizzyCo | K23: =Analyze!D58 -> 161210.1 | L23: =Analyze!E58 -> 2262827.1
C24: =Analyze!C39 -> Diet Coke | D24: =Analyze!D39 -> 423758.7 | E24: =Analyze!E39 -> 1633959.3 | F24: =Analyze!F39 -> 2057718 | J24: =Analyze!C59 -> Target | K24: =Analyze!D59 -> 9250.3 | L24: =Analyze!E59 -> 1341995
C25: =Analyze!C40 -> Fanta | D25: =Analyze!D40 -> 315489.2 | E25: =Analyze!E40 -> 1116062.9 | F25: =Analyze!F40 -> 1431552.1 | J25: =Analyze!C60 -> Walmart | K25: =Analyze!D60 -> 339912.5 | L25: =Analyze!E60 -> 580211
C26: =Analyze!C41 -> Powerade | D26: =Analyze!D41 -> 349533.9 | E26: =Analyze!E41 -> 1302529.3 | F26: =Analyze!F41 -> 1652063.2 | J26: =Analyze!C61 -> West Soda | K26: =Analyze!D61 -> 1170361.6 | L26: =Analyze!E61 -> 2070594.2
C27: =Analyze!C42 -> Sprite | D27: =Analyze!D42 -> 366578 | E27: =Analyze!E42 -> 1353578.3 | F27: =Analyze!F42 -> 1720156.3
C29: =Analyze!C43 -> Grand Total | D29: =Analyze!D43 -> 2423732.5 | E29: =Analyze!E43 -> 9592932.5 | F29: =Analyze!F43 -> 12016665
